Workbook

Sheet Sprint 1
A1: Project name: | C1: EDUMANAGE - HỆ THỐNG QUẢN LÝ THÔNG TIN SINH VIÊN VÀ ĐIỂM DANH LỚP HỌC TRỰC TUYẾN | F1: Kết thúc
A2: Module name: | C2: Sprint 1 | F2: Tăng ca
A3: Start date: | C3: 46250 | F3: Muộn
A4: End date: | C4: =W15 -> 46264 | F4: Chậm tiến độ
F5: Trước thời hạn
B6: SPRINT 1 REPORT
B7: No | C7: Thành viên | D7: Thực tế | E7: Ước tính | F7: Tên gọi tắt
B8: 1 | C8: Trần Xuân Vinh | D8: =SUMPRODUCT(ISNUMBER(SEARCH($F8,$E$16:$E$141))*$G$16:$G$141/(LEN($E$16:$E$141)-LEN(SUBSTITUTE($E$16:$E$141,",",""))+1))+SUMIF($E$16:$E$141,"All team",$G$16:$G$141)/COUNTA($F$8:$F$12) -> 62.633333 | E8: =SUMPRODUCT(ISNUMBER(SEARCH($F8,$E$16:$E$141))*$H$16:$H$141/(LEN($E$16:$E$141)-LEN(SUBSTITUTE($E$16:$E$141,",",""))+1))+SUMIF($E$16:$E$141,"All team",$H$16:$H$141)/COUNTA($F$8:$F$12) -> 62.633333 | F8: Vinh
B9: 2 | C9: Lê Huỳnh Tấn Thức | D9: =SUMPRODUCT(ISNUMBER(SEARCH($F9,$E$16:$E$141))*$G$16:$G$141/(LEN($E$16:$E$141)-LEN(SUBSTITUTE($E$16:$E$141,",",""))+1))+SUMIF($E$16:$E$141,"All team",$G$16:$G$141)/COUNTA($F$8:$F$12) -> 56.133333 | E9: =SUMPRODUCT(ISNUMBER(SEARCH($F9,$E$16:$E$141))*$H$16:$H$141/(LEN($E$16:$E$141)-LEN(SUBSTITUTE($E$16:$E$141,",",""))+1))+SUMIF($E$16:$E$141,"All team",$H$16:$H$141)/COUNTA($F$8:$F$12) -> 56.133333 | F9: Thức
B10: 3 | C10: Phùng Văn Cường | D10: =SUMPRODUCT(ISNUMBER(SEARCH($F10,$E$16:$E$141))*$G$16:$G$141/(LEN($E$16:$E$141)-LEN(SUBSTITUTE($E$16:$E$141,",",""))+1))+SUMIF($E$16:$E$141,"All team",$G$16:$G$141)/COUNTA($F$8:$F$12) -> 131.13333 | E10: =SUMPRODUCT(ISNUMBER(SEARCH($F10,$E$16:$E$141))*$H$16:$H$141/(LEN($E$16:$E$141)-LEN(SUBSTITUTE($E$16:$E$141,",",""))+1))+SUMIF($E$16:$E$141,"All team",$H$16:$H$141)/COUNTA($F$8:$F$12) -> 131.63333 | F10: Cường
B11: 4 | C11: Huỳnh Gia Pho | D11: =SUMPRODUCT(ISNUMBER(SEARCH($F11,$E$16:$E$141))*$G$16:$G$141/(LEN($E$16:$E$141)-LEN(SUBSTITUTE($E$16:$E$141,",",""))+1))+SUMIF($E$16:$E$141,"All team",$G$16:$G$141)/COUNTA($F$8:$F$12) -> 44.3 | E11: =SUMPRODUCT(ISNUMBER(SEARCH($F11,$E$16:$E$141))*$H$16:$H$141/(LEN($E$16:$E$141)-LEN(SUBSTITUTE($E$16:$E$141,",",""))+1))+SUMIF($E$16:$E$141,"All team",$H$16:$H$141)/COUNTA($F$8:$F$12) -> 38.8 | F11: Pho
B12: 5 | C12: Phan Quốc Trụ | D12: =SUMPRODUCT(ISNUMBER(SEARCH($F12,$E$16:$E$141))*$G$16:$G$141/(LEN($E$16:$E$141)-LEN(SUBSTITUTE($E$16:$E$141,",",""))+1))+SUMIF($E$16:$E$141,"All team",$G$16:$G$141)/COUNTA($F$8:$F$12) -> 16.3 | E12: =SUMPRODUCT(ISNUMBER(SEARCH($F12,$E$16:$E$141))*$H$16:$H$141/(LEN($E$16:$E$141)-LEN(SUBSTITUTE($E$16:$E$141,",",""))+1))+SUMIF($E$16:$E$141,"All team",$H$16:$H$141)/COUNTA($F$8:$F$12) -> 9.3 | F12: Trụ
B13: Tổng | D13: =SUM(D8:D12) -> 310.5 | E13: =SUM(E8:E12) -> 298.5
A15: Sprint | B15: Component | C15: Task name | E15: Responsible Member | G15: Thực tế | H15: Ước tính | I15: =$C$3 -> 46250 | J15: =I15+1 -> 46251 | K15: =J15+1 -> 46252 | L15: =K15+1 -> 46253 | M15: =L15+1 -> 46254 | N15: =M15+1 -> 46255 | O15: =N15+1 -> 46256 | P15: =O15+1 -> 46257 | Q15: =P15+1 -> 46258 | ... X15: =W15+1 -> 46265
A16: Sprint 1 | B16: Họp kế hoạch Sprint | E16: Vinh, Cường, Thức | G16: =4 -> 4 | H16: 4 | I16: 4 | J16: 0 | K16: 0 | L16: 0 | M16: 0 | N16: 0 | O16: 0 | P16: 0 | Q16: 0 | R16: 0 | S16: 0 | T16: 0 | U16: 0 | V16: 0 | W16: 0 | X16: 0
B17: Tạo Sprint Backlog 1 | E17: Cường | G17: =H17 -> 4 | H17: 4 | I17: 4 | J17: 0 | K17: 0 | L17: 0 | M17: 0 | N17: 0 | O17: 0 | P17: 0 | Q17: 0 | R17: 0 | S17: 0 | T17: 0 | U17: 0 | V17: 0 | W17: 0 | X17: 0
B18: Tạo tài liệu kiểm thử cho Sprint | E18: Cường | G18: =H18 -> 2 | H18: 2 | I18: 2 | J18: 0 | K18: 0 | L18: 0 | M18: 0 | N18: 0 | O18: 0 | P18: 0 | Q18: 0 | R18: 0 | S18: 0 | T18: 0 | U18: 0 | V18: 0 | W18: 0 | X18: 0
B19: User interface design | C19: Giao diện đăng nhập | E19: Pho | G19: =H19 -> 0.5 | H19: 0.5 | I19: 0.5 | J19: 0.5 | K19: 0 | L19: 0 | M19: 0 | N19: 0 | O19: 0 | P19: 0 | Q19: 0 | R19: 0 | S19: 0 | T19: 0 | U19: 0 | V19: 0 | W19: 0 | X19: 0
C20: Giao diện Dashboard | E20: Pho | G20: =H20 -> 4 | H20: 4 | I20: 4 | J20: 4 | K20: 0 | L20: 0 | M20: 0 | N20: 0 | O20: 0 | P20: 0 | Q20: 0 | R20: 0 | S20: 0 | T20: 0 | U20: 0 | V20: 0 | W20: 0 | X20: 0
C21: Giao diện hồ sơ cá nhân | E21: Trụ | G21: 1.5 | H21: 0.5 | I21: 0.5 | J21: 0.5 | K21: 0 | L21: 0 | M21: 0 | N21: 0 | O21: 0 | P21: 0 | Q21: 0 | R21: 0 | S21: 0 | T21: 0 | U21: 0 | V21: 0 | W21: 0 | X21: 0
K22: 1
C23: Giao diện quản lý môn học | E23: Trụ | G23: 1.5 | H23: 0.5 | I23: 0.5 | J23: 0.5 | K23: 0 | L23: 0 | M23: 0 | N23: 0 | O23: 0 | P23: 0 | Q23: 0 | R23: 0 | S23: 0 | T23: 0 | U23: 0 | V23: 0 | W23: 0 | X23: 0
K24: 1
C25: Giao diện quản lý lớp học phần | E25: Trụ | G25: 1.5 | H25: 0.5 | I25: 0.5 | J25: 0.5 | K25: 0 | L25: 0 | M25: 0 | N25: 0 | O25: 0 | P25: 0 | Q25: 0 | R25: 0 | S25: 0 | T25: 0 | U25: 0 | V25: 0 | W25: 0 | X25: 0
K26: 1
C27: Giao diện đăng ký lớp học phần | E27: Trụ | G27: 1.5 | H27: 0.5 | I27: 0.5 | J27: 0.5 | K27: 0 | L27: 0 | M27: 0 | N27: 0 | O27: 0 | P27: 0 | Q27: 0 | R27: 0 | S27: 0 | T27: 0 | U27: 0 | V27: 0 | W27: 0 | X27: 0
K28: 1
C29: Giao diện điểm danh bằng mã QR | E29: Trụ | G29: 1.5 | H29: 0.5 | I29: 0.5 | J29: 0.5 | K29: 0 | L29: 0 | M29: 0 | N29: 0 | O29: 0 | P29: 0 | Q29: 0 | R29: 0 | S29: 0 | T29: 0 | U29: 0 | V29: 0 | W29: 0 | X29: 0
K30: 1
C31: Giao diện quản lý điểm danh | E31: Trụ | G31: 1.5 | H31: 0.5 | I31: 0.5 | J31: 0.5 | K31: 0 | L31: 0 | M31: 0 | N31: 0 | O31: 0 | P31: 0 | Q31: 0 | R31: 0 | S31: 0 | T31: 0 | U31: 0 | V31: 0 | W31: 0 | X31: 0
K32: 1
C33: Giao diện nhập điểm | E33: Trụ | G33: 1.5 | H33: 0.5 | I33: 0.5 | J33: 0.5 | K33: 0 | L33: 0 | M33: 0 | N33: 0 | O33: 0 | P33: 0 | Q33: 0 | R33: 0 | S33: 0 | T33: 0 | U33: 0 | V33: 0 | W33: 0 | X33: 0
K34: 1
C35: Giao diện bảng điểm | E35: Cường | G35: 0.5 | H35: 0.5 | I35: 0.5 | J35: 0.5 | K35: 0 | L35: 0 | M35: 0 | N35: 0 | O35: 0 | P35: 0 | Q35: 0 | R35: 0 | S35: 0 | T35: 0 | U35: 0 | V35: 0 | W35: 0 | X35: 0
C36: Giao diện quản lý tài khoản | E36: Cường | G36: 0.5 | H36: 0.5 | I36: 0.5 | J36: 0.5 | K36: 0 | L36: 0 | M36: 0 | N36: 0 | O36: 0 | P36: 0 | Q36: 0 | R36: 0 | S36: 0 | T36: 0 | U36: 0 | V36: 0 | W36: 0 | X36: 0
C37: Giao diện phân công giảng dạy | E37: Cường | G37: 0.5 | H37: 0.5 | I37: 0.5 | J37: 0.5 | K37: 0 | L37: 0 | M37: 0 | N37: 0 | O37: 0 | P37: 0 | Q37: 0 | R37: 0 | S37: 0 | T37: 0 | U37: 0 | V37: 0 | W37: 0 | X37: 0
C38: Review all user interfaces of sprint 1 | E38: All team | G38: =H38 -> 14 | H38: 14 | I38: 14 | J38: 14 | K38: 14 | L38: 14 | M38: 14 | N38: 14 | O38: 0 | P38: 0 | Q38: 0 | R38: 0 | S38: 0 | T38: 0 | U38: 0 | V38: 0 | W38: 0 | X38: 0
B39: Design test case | C39: Thiết kế trường kiểm thử cho đăng nhập | E39: Cường | G39: =H39 -> 2 | H39: 2 | I39: 2 | J39: 2 | K39: 2 | L39: 0 | M39: 0 | N39: 0 | O39: 0 | P39: 0 | Q39: 0 | R39: 0 | S39: 0 | T39: 0 | U39: 0 | V39: 0 | W39: 0 | X39: 0
C40: Thiết kế trường kiểm thử cho đăng xuất | E40: Cường | G40: 1 | H40: 1 | I40: 1 | J40: 1 | K40: 1 | L40: 0 | M40: 0 | N40: 0 | O40: 0 | P40: 0 | Q40: 0 | R40: 0 | S40: 0 | T40: 0 | U40: 0 | V40: 0 | W40: 0 | X40: 0
C41: Thiết kế trường kiểm thử cho thông tin cá nhân | E41: Cường | G41: =H41 -> 2 | H41: 2 | I41: 2 | J41: 2 | K41: 2 | L41: 2 | M41: 0 | N41: 0 | O41: 0 | P41: 0 | Q41: 0 | R41: 0 | S41: 0 | T41: 0 | U41: 0 | V41: 0 | W41: 0 | X41: 0
...

Sheet Sprint 2
A1: Project name: | C1: EDUMANAGE - HỆ THỐNG QUẢN LÝ LỚP HỌC TRỰC TUYẾN VÀ ĐIỂM DANH | F1: Kết thúc
A2: Module name: | C2: Sprint 2 | F2: Tăng ca
A3: Start date: | C3: 46265 | F3: Muộn
A4: End date: | C4: 46280 | F4: Chậm tiến độ
F5: Trước thời hạn
B6: SPRINT 2 REPORT
B7: No | C7: Thành viên | D7: Thực tế | E7: Ước tính | F7: Tên gọi tắt
B8: 1 | C8: Trần Xuân Vinh | D8: =SUMPRODUCT(ISNUMBER(SEARCH($F8,$E$16:$E$81))*$G$16:$G$81/(LEN($E$16:$E$81)-LEN(SUBSTITUTE($E$16:$E$81,",",""))+1))+SUMIF($E$16:$E$81,"All team",$G$16:$G$81)/COUNTA($F$8:$F$12) -> 50.733333 | E8: =SUMPRODUCT(ISNUMBER(SEARCH($F8,$E$16:$E$81))*$H$16:$H$81/(LEN($E$16:$E$81)-LEN(SUBSTITUTE($E$16:$E$81,",",""))+1))+SUMIF($E$16:$E$81,"All team",$H$16:$H$81)/COUNTA($F$8:$F$12) -> 50.733333 | F8: Vinh
B9: 2 | C9: Lê Huỳnh Tấn Thức | D9: =SUMPRODUCT(ISNUMBER(SEARCH($F9,$E$16:$E$81))*$G$16:$G$81/(LEN($E$16:$E$81)-LEN(SUBSTITUTE($E$16:$E$81,",",""))+1))+SUMIF($E$16:$E$81,"All team",$G$16:$G$81)/COUNTA($F$8:$F$12) -> 95.733333 | E9: =SUMPRODUCT(ISNUMBER(SEARCH($F9,$E$16:$E$81))*$H$16:$H$81/(LEN($E$16:$E$81)-LEN(SUBSTITUTE($E$16:$E$81,",",""))+1))+SUMIF($E$16:$E$81,"All team",$H$16:$H$81)/COUNTA($F$8:$F$12) -> 95.733333 | F9: Thức
B10: 3 | C10: Phùng Văn Cường | D10: =SUMPRODUCT(ISNUMBER(SEARCH($F10,$E$16:$E$81))*$G$16:$G$81/(LEN($E$16:$E$81)-LEN(SUBSTITUTE($E$16:$E$81,",",""))+1))+SUMIF($E$16:$E$81,"All team",$G$16:$G$81)/COUNTA($F$8:$F$12) -> 26.733333 | E10: =SUMPRODUCT(ISNUMBER(SEARCH($F10,$E$16:$E$81))*$H$16:$H$81/(LEN($E$16:$E$81)-LEN(SUBSTITUTE($E$16:$E$81,",",""))+1))+SUMIF($E$16:$E$81,"All team",$H$16:$H$81)/COUNTA($F$8:$F$12) -> 26.733333 | F10: Cường
B11: 4 | C11: Huỳnh Gia Pho | D11: =SUMPRODUCT(ISNUMBER(SEARCH($F11,$E$16:$E$81))*$G$16:$G$81/(LEN($E$16:$E$81)-LEN(SUBSTITUTE($E$16:$E$81,",",""))+1))+SUMIF($E$16:$E$81,"All team",$G$16:$G$81)/COUNTA($F$8:$F$12) -> 16.4 | E11: =SUMPRODUCT(ISNUMBER(SEARCH($F11,$E$16:$E$81))*$H$16:$H$81/(LEN($E$16:$E$81)-LEN(SUBSTITUTE($E$16:$E$81,",",""))+1))+SUMIF($E$16:$E$81,"All team",$H$16:$H$81)/COUNTA($F$8:$F$12) -> 16.4 | F11: Pho
B12: 5 | C12: Phan Quốc Trụ | D12: {=SUMPRODUCT(ISNUMBER(SEARCH($F12,$E$16:$E$81))*$G$16:$G$81/(LEN($E$16:$E$81)-LEN(SUBSTITUTE($E$16:$E$81,",",""))+1))+SUMIF($E$16:$E$81,"All team",$G$16:$G$81)/COUNTA($F$8:$F$12)} -> 27.4 | E12: =SUMPRODUCT(ISNUMBER(SEARCH($F12,$E$16:$E$81))*$H$16:$H$81/(LEN($E$16:$E$81)-LEN(SUBSTITUTE($E$16:$E$81,",",""))+1))+SUMIF($E$16:$E$81,"All team",$H$16:$H$81)/COUNTA($F$8:$F$12) -> 11.4 | F12: Trụ
B13: Tổng | D13: =SUM(D8:D12) -> 217 | E13: =SUM(E8:E12) -> 201
A15: Sprint | B15: Component | C15: Task name | E15: Responsible Member | G15: Thực tế | H15: Ước tính | I15: =$C$3 -> 46265 | J15: =I15+1 -> 46266 | K15: =J15+1 -> 46267 | L15: =K15+1 -> 46268 | M15: =L15+1 -> 46269 | N15: =M15+1 -> 46270 | O15: =N15+1 -> 46271 | P15: =O15+1 -> 46272 | Q15: =P15+1 -> 46273 | ... Y15: =X15+1 -> 46281
A16: Sprint 2 | B16: Họp kế hoạch Sprint | E16: Vinh, Cường, Thức | G16: 5 | H16: 5 | I16: 5 | J16: 0 | K16: 0 | L16: 0 | M16: 0 | N16: 0 | O16: 0 | P16: 0 | Q16: 0 | R16: 0 | S16: 0 | T16: 0 | U16: 0 | V16: 0 | W16: 0 | X16: 0 | Y16: 0
B17: Tạo Sprint Backlog 2 | E17: Thức | G17: 5 | H17: 5 | I17: 5 | J17: 0 | K17: 0 | L17: 0 | M17: 0 | N17: 0 | O17: 0 | P17: 0 | Q17: 0 | R17: 0 | S17: 0 | T17: 0 | U17: 0 | V17: 0 | W17: 0 | X17: 0 | Y17: 0
B18: Tạo tài liệu kiểm thử cho Sprint | E18: Thức | G18: 2 | H18: 2 | I18: 2 | J18: 0 | K18: 0 | L18: 0 | M18: 0 | N18: 0 | O18: 0 | P18: 0 | Q18: 0 | R18: 0 | S18: 0 | T18: 0 | U18: 0 | V18: 0 | W18: 0 | X18: 0 | Y18: 0
B19: User interface design | C19: Giao diện lịch học | E19: Trụ | G19: 6 | H19: 2 | I19: 2 | J19: 2 | K19: 0 | L19: 0 | M19: 0 | N19: 0 | O19: 0 | P19: 0 | Q19: 0 | R19: 0 | S19: 0 | T19: 0 | U19: 0 | V19: 0 | W19: 0 | X19: 0 | Y19: 0
K20: 4 | Y20: 0
C21: Giao diện phòng học trực tuyến | E21: Trụ | G21: 6 | H21: 2 | I21: 2 | J21: 2 | K21: 0 | L21: 0 | M21: 0 | N21: 0 | O21: 0 | P21: 0 | Q21: 0 | R21: 0 | S21: 0 | T21: 0 | U21: 0 | V21: 0 | W21: 0 | X21: 0 | Y21: 0
K22: 4 | Y22: 0
C23: Giao diện xin phép vắng | E23: Trụ | G23: 6 | H23: 2 | I23: 2 | J23: 2 | K23: 0 | L23: 0 | M23: 0 | N23: 0 | O23: 0 | P23: 0 | Q23: 0 | R23: 0 | S23: 0 | T23: 0 | U23: 0 | V23: 0 | W23: 0 | X23: 0 | Y23: 0
K24: 4 | Y24: 0
C25: Giao diện danh sách đơn xin phép chờ duyệt | E25: Trụ | G25: 6 | H25: 2 | I25: 2 | J25: 2 | K25: 0 | L25: 0 | M25: 0 | N25: 0 | O25: 0 | P25: 0 | Q25: 0 | R25: 0 | S25: 0 | T25: 0 | U25: 0 | V25: 0 | W25: 0 | X25: 0 | Y25: 0
K26: 4 | Y26: 0
C27: Giao diện thống kê và xuất báo cáo | E27: Cường | G27: =H27 -> 2 | H27: 2 | I27: 2 | J27: 2 | K27: 0 | L27: 0 | M27: 0 | N27: 0 | O27: 0 | P27: 0 | Q27: 0 | R27: 0 | S27: 0 | T27: 0 | U27: 0 | V27: 0 | W27: 0 | X27: 0 | Y27: 0
C28: Sơ đồ liên kết giao diện | E28: Vinh | G28: =H28 -> 2 | H28: 2 | I28: 2 | J28: 2 | K28: 0 | L28: 0 | M28: 0 | N28: 0 | O28: 0 | P28: 0 | Q28: 0 | R28: 0 | S28: 0 | T28: 0 | U28: 0 | V28: 0 | W28: 0 | X28: 0 | Y28: 0
C29: Review all user interfaces of sprint 2 | E29: All team | G29: 2 | H29: 2 | I29: 2 | J29: 2 | K29: 2 | L29: 2 | M29: 0 | N29: 0 | O29: 0 | P29: 0 | Q29: 0 | R29: 0 | S29: 0 | T29: 0 | U29: 0 | V29: 0 | W29: 0 | X29: 0 | Y29: 0
B30: Design test case | C30: Thiết kế trường kiểm thử cho xem lịch học | E30: Thức | G30: =H30 -> 2 | H30: 2 | I30: 2 | J30: 2 | K30: 2 | L30: 2 | M30: 0 | N30: 0 | O30: 0 | P30: 0 | Q30: 0 | R30: 0 | S30: 0 | T30: 0 | U30: 0 | V30: 0 | W30: 0 | X30: 0 | Y30: 0
C31: Thiết kế trường kiểm thử cho mở phòng học trực tuyến | E31: Thức | G31: =H31 -> 4 | H31: 4 | I31: 4 | J31: 4 | K31: 4 | L31: 4 | M31: 4 | N31: 4 | O31: 0 | P31: 0 | Q31: 0 | R31: 0 | S31: 0 | T31: 0 | U31: 0 | V31: 0 | W31: 0 | X31: 0 | Y31: 0
C32: Thiết kế trường kiểm thử cho tham gia lớp học trực tuyến | E32: Thức | G32: =H32 -> 4 | H32: 4 | I32: 4 | J32: 4 | K32: 4 | L32: 4 | M32: 4 | N32: 4 | O32: 4 | P32: 0 | Q32: 0 | R32: 0 | S32: 0 | T32: 0 | U32: 0 | V32: 0 | W32: 0 | X32: 0 | Y32: 0
C33: Thiết kế trường kiểm thử cho quản lý lớp học trực tuyến | E33: Thức | G33: =H33 -> 2 | H33: 2 | I33: 2 | J33: 2 | K33: 2 | L33: 2 | M33: 2 | N33: 2 | O33: 2 | P33: 2 | Q33: 2 | R33: 0 | S33: 0 | T33: 0 | U33: 0 | V33: 0 | W33: 0 | X33: 0 | Y33: 0
C34: Thiết kế trường kiểm thử cho tương tác trong lớp | E34: Thức | G34: =H34 -> 3 | H34: 3 | I34: 3 | J34: 3 | K34: 3 | L34: 3 | M34: 3 | N34: 3 | O34: 3 | P34: 3 | Q34: 3 | R34: 3 | S34: 3 | T34: 0 | U34: 0 | V34: 0 | W34: 0 | X34: 0 | Y34: 0
C35: Thiết kế trường kiểm thử cho gửi yêu cầu xin phép vắng | E35: Pho, Cường | G35: =H35 -> 2 | H35: 2 | I35: 2 | J35: 2 | K35: 2 | L35: 2 | M35: 2 | N35: 2 | O35: 2 | P35: 2 | Q35: 2 | R35: 2 | S35: 2 | T35: 2 | U35: 0 | V35: 0 | W35: 0 | X35: 0 | Y35: 0
C36: Thiết kế trường kiểm thử cho xuất báo cáo điểm danh | E36: Thức | G36: 3 | H36: 3 | I36: 3 | J36: 3 | K36: 3 | L36: 3 | M36: 3 | N36: 3 | O36: 3 | P36: 3 | Q36: 3 | R36: 3 | S36: 3 | T36: 3 | U36: 3 | V36: 0 | W36: 0 | X36: 0 | Y36: 0
C37: Thiết kế trường kiểm thử cho thống kê, báo cáo hệ thống | E37: Thức | G37: =H37 -> 4 | H37: 4 | I37: 4 | J37: 4 | K37: 4 | L37: 4 | M37: 4 | N37: 4 | O37: 4 | P37: 4 | Q37: 4 | R37: 4 | S37: 4 | T37: 4 | U37: 4 | V37: 4 | W37: 4 | X37: 0 | Y37: 0
C38: Review all test case of sprint 2 | E38: All team | G38: =H38 -> 5 | H38: 5 | I38: 5 | J38: 5 | K38: 5 | L38: 5 | M38: 5 | N38: 5 | O38: 5 | P38: 5 | Q38: 5 | R38: 5 | S38: 5 | T38: 5 | U38: 5 | V38: 5 | W38: 5 | X38: 5 | Y38: 0
B39: Coding | C39: Thiết kế front-end cho xem lịch học | E39: Thức | G39: =H39 -> 4 | H39: 4 | I39: 4 | J39: 4 | K39: 4 | L39: 4 | M39: 0 | N39: 0 | O39: 0 | P39: 0 | Q39: 0 | R39: 0 | S39: 0 | T39: 0 | U39: 0 | V39: 0 | W39: 0 | X39: 0 | Y39: 0
C40: Code back-end cho xem lịch học | E40: Vinh | G40: =H40 -> 6 | H40: 6 | I40: 6 | J40: 6 | K40: 6 | L40: 6 | M40: 0 | N40: 0 | O40: 0 | P40: 0 | Q40: 0 | R40: 0 | S40: 0 | T40: 0 | U40: 0 | V40: 0 | W40: 0 | X40: 0 | Y40: 0
C41: Thiết kế front-end cho mở phòng học trực tuyến | E41: Thức | G41: 4 | H41: 4 | I41: 4 | J41: 4 | K41: 4 | L41: 4 | M41: 4 | N41: 0 | O41: 0 | P41: 0 | Q41: 0 | R41: 0 | S41: 0 | T41: 0 | U41: 0 | V41: 0 | W41: 0 | X41: 0 | Y41: 0
...

Sheet Total
A1: SPRINT BACKLOG REPORT
B2: ='Sprint 1'!$F$8 -> Vinh | D2: ='Sprint 1'!$F$9 -> Thức | F2: ='Sprint 1'!$F$10 -> Cường | H2: ='Sprint 1'!$F$11 -> Pho | J2: ='Sprint 1'!$F$12 -> Trụ
B3: Thực tế | C3: Ước tính | D3: Thực tế | E3: Ước tính | F3: Thực tế | G3: Ước tính | H3: Thực tế | I3: Ước tính | J3: Thực tế | K3: Ước tính
A4: Sprint 1 | B4: ='Sprint 1'!$D$8 -> 62.633333 | C4: ='Sprint 1'!$E$8 -> 62.633333 | D4: ='Sprint 1'!$D$9 -> 56.133333 | E4: ='Sprint 1'!$E$9 -> 56.133333 | F4: ='Sprint 1'!$D$10 -> 131.13333 | G4: ='Sprint 1'!$E$10 -> 131.63333 | H4: ='Sprint 1'!$D$11 -> 44.3 | I4: ='Sprint 1'!$E$11 -> 38.8 | J4: ='Sprint 1'!$D$12 -> 16.3 | K4: ='Sprint 1'!$E$12 -> 9.3
A5: Sprint 2 | B5: ='Sprint 2'!$D$8 -> 50.733333 | C5: ='Sprint 2'!$E$8 -> 50.733333 | D5: ='Sprint 2'!$D$9 -> 95.733333 | E5: ='Sprint 2'!$E$9 -> 95.733333 | F5: ='Sprint 2'!$D$10 -> 26.733333 | G5: ='Sprint 2'!$E$10 -> 26.733333 | H5: ='Sprint 2'!$D$11 -> 16.4 | I5: ='Sprint 2'!$E$11 -> 16.4 | J5: ='Sprint 2'!$D$12 -> 27.4 | K5: ='Sprint 2'!$E$12 -> 11.4
A6: Tổng | B6: =SUM(B4:B5) -> 113.36667 | C6: =SUM(C4:C5) -> 113.36667 | D6: =SUM(D4:D5) -> 151.86667 | E6: =SUM(E4:E5) -> 151.86667 | F6: =SUM(F4:F5) -> 157.86667 | G6: =SUM(G4:G5) -> 158.36667 | H6: =SUM(H4:H5) -> 60.7 | I6: =SUM(I4:I5) -> 55.2 | ... K6: =SUM(K4:K5) -> 20.7
E9: FINAL TOTAL
E10: Thực tế | F10: =SUMIF($B$3:$K$3,"Thực tế",$B$6:$K$6) -> 527.5
E11: Ước tính | F11: =SUMIF($B$3:$K$3,"Ước tính",$B$6:$K$6) -> 499.5
